Workbook

Sheet Deal Tracker
A1: =TODAY() -> 46116
C2: Property Name | D2: City | E2: State | F2: Stage | G2: Purchase Price | H2: Property Type | I2: Total Slips/Racks | J2: Est Occ% | K2: Source | L2: Ownership | M2: SM Prospect? | N2: Acres | O2: Notes | P2: Closing Status
C4: ANALYZING
A5: Year | B5: Financials? | C5: Marina Name | D5: Info Received | E5: Time In Progress | F5: Deadline | G5: Time to Deadline | H5: City | I5: State | J5: Deal Source | K5: Total Slips/Racks/RV Sites | L5: List/Expected Price | M5: SM Price | N5: Discount to List | O5: Status | P5: SM Prospect? | Q5: Notes
A6: 2024 | C6: Stock Island Land | E6: =IFERROR(IF(C6="","",IF(($A$1-D6)>45000,"Waiting on Info",$A$1-D6)),"") -> Waiting on Info | F6: =IF(D6="","TBD",10+D6) -> TBD | G6: =IFERROR(IF(F6="","",F6-$A$1),"n/a") -> n/a | H6: Stock Island | I6: FL | J6: Broker | K6: 127 | L6: Market | M6: 7000000 | N6: =IFERROR(IF(AND(AND(L6<>"Market",L6<>"TBD"),M6<>"TBD"),M6/L6,""),"") | O6: Completed | P6: Yes | Q6: Expansion to Stock Island
A7: 2023 | B7: Yes | C7: Cat's Paw Marina | D7: 45681 | E7: =IFERROR(IF(C7="","",IF(($A$1-D7)>45000,"Waiting on Info",$A$1-D7)),"") -> 435 | F7: 45703 | G7: =IFERROR(IF(F7="","",F7-$A$1),"n/a") -> -413 | H7: St. Augustine | I7: FL | J7: Broker | K7: 700 | L7: 50000000 | M7: 15000000 | N7: =IFERROR(IF(AND(AND(L7<>"Market",L7<>"TBD"),M7<>"TBD"),M7/L7,""),"") -> 0.3 | O7: Finalizing | P7: Yes | Q7: Now on market with CB - Seller said she'd entertain a JV or clean exit - too big a project for her to complete alone; Cost basis is rich; too much weight on FV and exit - returns not there and seller sticking to profit expectations.
A8: 2025 | B8: Yes | C8: Port Dania | D8: 45686 | E8: =IFERROR(IF(C8="","",IF(($A$1-D8)>45000,"Waiting on Info",$A$1-D8)),"") -> 430 | F8: TBD | G8: =IFERROR(IF(F8="","",F8-$A$1),"n/a") -> n/a | H8: Dania Beach | I8: FL | J8: Broker | K8: 220 | L8: 25000000 | M8: TBD | N8: =IFERROR(IF(AND(AND(L8<>"Market",L8<>"TBD"),M8<>"TBD"),M8/L8,""),"") | O8: In Progress | P8: Yes | Q8: CBRE; we'd want F3 FTL over this opp.
A9: 2024 | B9: Yes | C9: Sands Harbor Marina | D9: 45531 | E9: =IFERROR(IF(C9="","",IF(($A$1-D9)>45000,"Waiting on Info",$A$1-D9)),"") -> 585 | F9: TBD | G9: =IFERROR(IF(F9="","",F9-$A$1),"n/a") -> n/a | H9: Pompano Beach | I9: FL | J9: Off-Market | K9: 50 | L9: 24500000 | M9: 21000000 | N9: =IFERROR(IF(AND(AND(L9<>"Market",L9<>"TBD"),M9<>"TBD"),M9/L9,""),"") -> 0.85714286 | O9: Completed | P9: Yes | Q9: Was on market with CBRE 2x; reviewing latest information.
A10: 2025 | B10: Yes | C10: Kirkland Homeport Marina | D10: 45720 | E10: =IFERROR(IF(C10="","",IF(($A$1-D10)>45000,"Waiting on Info",$A$1-D10)),"") -> 396 | F10: ASAP | G10: =IFERROR(IF(F10="","",F10-$A$1),"n/a") -> n/a | H10: Kirkland | I10: WA | J10: Off-Market | K10: 118 | L10: 55000000 | M10: TBD | O10: In Progress | P10: Yes | Q10: Engaging a few groups; Suntex is one of them; excellent facility
A11: 2024 | B11: Yes | C11: King Harbor Marina | D11: 45456 | E11: =IFERROR(IF(C11="","",IF(($A$1-D11)>45000,"Waiting on Info",$A$1-D11)),"") -> 660 | F11: ASAP | G11: =IFERROR(IF(F11="","",F11-$A$1),"n/a") -> n/a | H11: Redondo Beach | I11: CA | J11: Broker | K11: 857 | L11: 115000000 | M11: 85000000 | N11: =IFERROR(IF(AND(AND(L11<>"Market",L11<>"TBD"),M11<>"TBD"),M11/L11,""),"") -> 0.73913043 | O11: In Progress | P11: Yes | Q11: Need to get longer lease; tied to capex spend on property
A12: 2023 | B12: Yes | C12: Eastport Yacht Center | D12: 45713 | E12: =IFERROR(IF(C12="","",IF(($A$1-D12)>45000,"Waiting on Info",$A$1-D12)),"") -> 403 | F12: ASAP | G12: =IFERROR(IF(F12="","",F12-$A$1),"n/a") -> n/a | H12: Annapolis | I12: Maryland | J12: Off-Market | K12: 111 | L12: Market | M12: 11000000 | N12: =IFERROR(IF(AND(L12<>"Market",M12<>"TBD"),M12/L12,""),"") | O12: Completed | P12: Yes | Q12: Future opportunity to acquire land in between for additional slips and upland amenities.
A13: 2025 | B13: Yes | C13: HAVN | D13: 45686 | E13: =IFERROR(IF(C13="","",IF(($A$1-D13)>45000,"Waiting on Info",$A$1-D13)),"") -> 430 | F13: 45695 | G13: =IFERROR(IF(F13="","",F13-$A$1),"n/a") -> -421 | H13: Palm Beach | I13: FL | J13: Broker | K13: 50 | L13: 40000000 | M13: 15000000 | N13: =IFERROR(IF(AND(AND(L13<>"Market",L13<>"TBD"),M13<>"TBD"),M13/L13,""),"") -> 0.375 | O13: In Progress | P13: Yes | Q13: CBRE
A14: 2025 | B14: Yes | C14: Xtreme Cove Marina | D14: 45715 | E14: =IFERROR(IF(C14="","",IF(($A$1-D14)>45000,"Waiting on Info",$A$1-D14)),"") -> 401 | F14: 45741 | G14: =IFERROR(IF(F14="","",F14-$A$1),"n/a") -> -375 | H14: Eufaula | I14: OK | J14: Broker | K14: 404 | L14: 15000000 | M14: TBD | O14: In Progress | P14: Yes | Q14: Low rates; 400+ slips; opportunity to expand by 200; more to uncover; largest on this lake.
A15: 2024 | B15: Yes | C15: USVI Marinas (2) | D15: 45405 | E15: =IFERROR(IF(C15="","",IF(($A$1-D15)>45000,"Waiting on Info",$A$1-D15)),"") -> 711 | F15: TBD | G15: =IFERROR(IF(F15="","",F15-$A$1),"n/a") -> n/a | H15: St. Thomas | I15: USVI | J15: Broker | K15: =172+120+90 -> 382 | L15: 35000000 | M15: 30000000 | N15: =IFERROR(IF(AND(AND(L15<>"Market",L15<>"TBD"),M15<>"TBD"),M15/L15,""),"") -> 0.85714286 | O15: In Progress | P15: Yes
A16: 2024 | B16: Yes | C16: Oakdale Yacht Club | D16: 45303 | E16: =IFERROR(IF(($A$1-D16)>45000,"Waiting on Info",$A$1-D16),"") -> 813 | F16: ASAP | G16: =IFERROR(IF(F16="","",F16-$A$1),"n/a") -> n/a | H16: Oakdale | I16: NY | J16: Off-Market | K16: 750 | L16: 40000000 | M16: 20000000 | N16: =IFERROR(IF(AND(AND(L16<>"Market",L16<>"TBD"),M16<>"TBD"),M16/L16,""),"") -> 0.5 | O16: In Progress | P16: Yes
A17: 2025 | B17: Yes | C17: Madiera Dev Site | D17: 45707 | E17: =IFERROR(IF(C17="","",IF(($A$1-D17)>45000,"Waiting on Info",$A$1-D17)),"") -> 409 | F17: TBD | G17: =IFERROR(IF(F17="","",F17-$A$1),"n/a") -> n/a | H17: Madeira Beach | I17: FL | J17: Off-Market | K17: 89 | L17: 28000000 | M17: TBD | O17: In Progress | P17: Yes | Q17: Development of wet slips; upland might be available as well, but at this stage just wet slips; 69-89
A18: 2025 | B18: Yes | C18: Mangrove Marina | D18: 45686 | E18: =IFERROR(IF(C18="","",IF(($A$1-D18)>45000,"Waiting on Info",$A$1-D18)),"") -> 430 | F18: 45731 | G18: =IFERROR(IF(F18="","",F18-$A$1),"n/a") -> -385 | H18: Key Largo | I18: FL | J18: Broker | K18: 299 | L18: 25000000 | M18: 15000000 | N18: =IFERROR(IF(AND(AND(L18<>"Market",L18<>"TBD"),M18<>"TBD"),M18/L18,""),"") -> 0.6 | O18: Finalizing | P18: Yes | Q18: CBRE
A19: 2025 | B19: Yes | C19: JDF Marina | D19: 45715 | E19: =IFERROR(IF(C19="","",IF(($A$1-D19)>45000,"Waiting on Info",$A$1-D19)),"") -> 401 | F19: TBD | G19: =IFERROR(IF(F19="","",F19-$A$1),"n/a") -> n/a | H19: Panama City Beach | I19: FL | J19: Broker | L19: 11000000 | M19: TBD | O19: In Progress | P19: Yes | Q19: Development opportunity
G21: =IFERROR(IF(F21="","",F21-$A$1),"n/a")
B22: =COUNTIF(B9:B21,"<>") -> 11 | C22: =COUNTIF(C9:C21,"<>") -> 11 | J22: =COUNTIF(J9:J21,"Off-Market") -> 5 | K22: =SUM(K9:K21) -> 3110 | L22: =SUM(L9:L21) -> 388500000 | M22: =SUM(M9:M21) -> 197000000 | N22: =IFERROR(AVERAGE(N158:N158),0) -> 0 | O22: =COUNTIF(O9:O21,"<>") -> 11
A23: =COUNTIF($A$9:$A$21,"2023") -> 1 | B23: = 2023 Deals | J23: # Off-Market
A24: =COUNTIF($A$9:$A$21,"2024") -> 4 | B24: = 2024 Deals
A25: =COUNTIF($A$9:$A$21,"2025") -> 6 | B25: = 2025 Deals
C27: ACTIVE DEALS | Q27: Notes
A28: Year | B28: Financials? | C28: Marina Name | D28: List/Expected Price | E28: Offer Price | F28: LOI Date | G28: Time Since LOI | H28: City | I28: State | J28: Deal Source | K28: Total Slips/Racks/RV Sites | L28: Acres | M28: Ownership | N28: Discount to List | O28: Status | P28: SM Prospect?
A29: 2024 | B29: Yes | C29: Hingham Shipyard Marinas | D29: 60000000 | E29: 62000000 | F29: 45712 | G29: =IFERROR(IF(F29="","",$A$1-F29),"n/a") -> 404 | H29: Hingham | I29: MA | J29: Off-Market | K29: =550+85 -> 635 | L29: 55.16 | M29: Fee Simple; License | N29: =IF(AND(AND(D29<>"Market",D29<>"TBD"),E29<>"TBD"),E29/D29,"") -> 1.0333333 | O29: LOI Submitted | P29: Yes | Q29: Other bidders reviewing information.
A30: 2025 | B30: Yes | C30: Castaways Yacht Club | D30: 21000000 | E30: 20000000 | F30: 45712 | G30: =IFERROR(IF(F30="","",F30-$A$1),"n/a") -> -404 | H30: New Rochelle | I30: NY | J30: Broker | K30: 130 | M30: Fee Simple | N30: =IF(AND(AND(D30<>"Market",D30<>"TBD"),E30<>"TBD"),E30/D30,"") -> 0.95238095 | O30: LOI Submitted | P30: Yes | Q30: Seller wants to retain dealership/brokerage and pay marina owner rent.
A31: 2025 | B31: Yes | C31: Sundance Marina Jensen Beach | D31: 20500000 | E31: 17000000 | F31: 45714 | G31: =IFERROR(IF(F31="","",F31-$A$1),"n/a") -> -402 | H31: Stuart | I31: FL | J31: Broker | K31: 270 | M31: Fee Simple | N31: =IF(AND(AND(D31<>"Market",D31<>"TBD"),E31<>"TBD"),E31/D31,"") -> 0.82926829 | O31: LOI Submitted | P31: Yes | Q31: OneWater lease expires Jan. 2026; full marina comes in-house at that time.
A32: 2024 | B32: Yes | C32: Surfside 3 Marina | D32: 18500000 | E32: 16500000 | F32: 45721 | G32: =IFERROR(IF(F32="","",F32-$A$1),"n/a") -> -395 | H32: Lindenhurst | I32: NY | J32: Off-Market | K32: 550 | M32: Fee Simple | N32: =IF(AND(AND(D32<>"Market",D32<>"TBD"),E32<>"TBD"),E32/D32,"") -> 0.89189189 | O32: LOI Submitted | P32: Yes | Q32: Upside in storage capacity; 35' avg. boat length; synergies with West Shore; opp. with fuel, club, etc.
A33: 2023 | B33: Yes | C33: Hidden Harbor Marina | D33: 50000000 | E33: 26000000 | F33: TBD | G33: =IFERROR(IF(F33="","",$A$1-F33),"n/a") -> n/a | H33: Sarasota | I33: FL | J33: Off-Market | K33: 320 | L33: 2.71 | M33: Fee Simple; SLL | N33: =IF(AND(AND(D33<>"Market",D33<>"TBD"),E33<>"TBD"),E33/D33,"") -> 0.52 | O33: LOI Ready | P33: Yes | Q33: Revenue reimbursements on CAM, Prop Taxes, Prop Insurance; Racks have amendments to MPP
A34: 2024 | C34: All Seasons Land | D34: 1400000 | E34: 1400000 | F34: TBD | G34: =IFERROR(IF(F34="","",$A$1-F34),"n/a") -> n/a | H34: Marmora | I34: NJ | J34: Off-Market | K34: n/a | L34: 1.5 | M34: Fee Simple | N34: =IF(AND(AND(D34<>"Market",D34<>"TBD"),E34<>"TBD"),E34/D34,"") -> 1 | O34: On Hold | P34: Yes | Q34: Additional land to absorb into All Seasons.
G35: =IFERROR(IF(F35="","",$A$1-F35),"n/a") | N35: =IFERROR(IF(AND(AND(D35<>"Market",D35<>"TBD"),E35<>"TBD"),E35/D35,""),"")
B36: =COUNTIF(B29:B35,"<>") -> 5 | C36: =COUNTIF(C29:C35,"<>") -> 6 | E36: =SUM(E29:E35) -> 142900000 | J36: =COUNTIF(J29:J35,"Off-Market") -> 4 | K36: =SUM(K29:K35) -> 1905 | L36: =SUM(L29:L35) -> 59.37 | N36: =IFERROR(AVERAGE(N29:N34),0) -> 0.87114575
A37: =COUNTIF($A$29:$A$35,"2023") -> 1 | B37: = 2023 Deals | J37: # Off-Market
A38: =COUNTIF($A$29:$A$35,"2024") -> 3 | B38: = 2024 Deals
A39: =COUNTIF($A$29:$A$35,"2025") -> 2 | B39: = 2025 Deals
C41: LONG TERM | Q41: Notes
A42: Year | B42: Financials? | C42: Marina Name | D42: Info Received | E42: Time In Progress | F42: Deadline | G42: Time to Deadline | H42: City | I42: State | J42: Deal Source | K42: Total Slips/Racks/RV Sites | L42: List/Expected Price | M42: SM Price | N42: Discount to List | O42: Status | P42: SM Prospect?
A43: 2024 | C43: Eldean Shipyard | E43: =IFERROR(IF(C43="","",IF(($A$1-D43)>45000,"Waiting on Info",$A$1-D43)),"") -> Waiting on Info | H43: Macatawa | I43: MI | J43: Broker | L43: 30000000 | M43: TBD | N43: =IFERROR(IF(AND(AND(L43<>"Market",L43<>"TBD"),M43<>"TBD"),M43/L43,""),"") | O43: On Hold | P43: Yes
A44: 2023 | C44: Quality Boats of Charlotte Harbor | E44: =IFERROR(IF(C44="","",IF(($A$1-D44)>45000,"Waiting on Info",$A$1-D44)),"") -> Waiting on Info | H44: Englewood | I44: FL | J44: Off-Market | L44: 10000000 | M44: TBD | N44: =IFERROR(IF(AND(AND(L44<>"Market",L44<>"TBD"),M44<>"TBD"),M44/L44,""),"") | O44: On Hold | Q44: Not the best location; expecting high supply for lower demand area; reinvestment from Port 32 and ELS expected at neighboring locations; Gasparilla Marina also in this market...
...

Sheet M&A Deal Sheet
A1: 46118
C2: SM Pipeline | F2: 2026 YTD | I2: 2025 | L2: 2024 Total
C4: Under Contract | D4: =G20 -> 148600000 | F4: Deals Evaluated | G4: =D284 -> 16 | I4: Deals Evaluated | J4: =D283 -> 73 | L4: Deals Evaluated | M4: =D282 -> 92
C5: Under LOI | D5: =G31 -> 129400000 | F5: Financials Received | G5: =C284 -> 12 | H5: =IFERROR(G5/$G$4,"n/a") -> 0.75 | I5: Financials Received | J5: =C283 -> 45 | K5: =IFERROR(J5/$J$4,"n/a") -> 0.61643836 | L5: Financials Received | M5: =C282 -> 58 | N5: =M5/M4 -> 0.63043478
C6: Submitted Offers/To Be Submitted | D6: =G45 -> 654150000 | F6: LOIs Issued | G6: =COUNTIFS($P$15:$P$268,"2026",$Q$15:$Q$268,"<>"&"") -> 5 | H6: =G6/G4 -> 0.3125 | I6: LOIs Issued | J6: =COUNTIFS($P$15:$P$268,"2025",$Q$15:$Q$268,"<>"&"") -> 12 | K6: =J6/J4 -> 0.16438356 | L6: LOIs Issued | M6: 1 | N6: =M6/M4 -> 0.010869565
C7: Analyzing | D7: =G60 -> 607000000 | F7: LOIs Signed | G7: =COUNTIFS($P$15:$P$268,"2026",$R$15:$R$268,"<>"&"") -> 2 | H7: =IFERROR(G7/G6,"n/a") -> 0.4 | I7: LOIs Signed | J7: =COUNTIFS($P$15:$P$268,"2025",$R$15:$R$268,"<>"&"") -> 5 | K7: =J7/J6 -> 0.41666667 | L7: LOIs Signed | M7: =COUNTIFS($P$19:$P$268,"2024",$R$19:$R$268,"<>"&"") -> 0 | N7: =M7/M6 -> 0
C8: Long-Term | D8: =G108 -> 622000000 | F8: Closed/Expected to Close | G8: 2 | I8: Closed/Expected to Close | J8: 0 | L8: Closed/Expected to Close | M8: 0
D9: =SUM(D4:D8) -> 2161150000 | F9: Off-Market | G9: =L284 -> 4 | H9: =IFERROR(G9/$G$4,"n/a") -> 0.25 | I9: Off-Market | J9: =L283 -> 25 | K9: =IFERROR(J9/$J$4,"n/a") -> 0.34246575 | L9: Off-Market | M9: =L282 -> 45 | N9: =M9/M4 -> 0.48913043
F10: SM Prospects | G10: =N284 -> 2 | H10: =IFERROR(G10/$G$4,"n/a") -> 0.125 | I10: SM Prospects | J10: =N283 -> 22 | K10: =IFERROR(J10/$J$4,"n/a") -> 0.30136986 | L10: SM Prospects | M10: =N282 -> 33 | N10: =M10/M4 -> 0.35869565
C11: Opportunities Reviewed | D11: =G268 -> 1588199000 | F11: % of LOIs Off-Market | G11: =COUNTIFS($P$15:$P$268,"2026",$Q$15:$Q$268,"<>"&"",$L$15:$L$268,"Off-Market")/J6 -> 0.16666667 | I11: % of LOIs Off-Market | J11: =COUNTIFS($P$15:$P$268,"2025",$Q$15:$Q$268,"<>"&"",$L$15:$L$268,"Off-Market")/J6 -> 0.5 | L11: % of LOIs Off-Market | M11: =COUNTIFS($P$19:$P$268,"2024",$Q$19:$Q$268,"<>"&"",$L$19:$L$268,"Off-Market")/M6 -> 0
C12: Total Underwritten | D12: =SUM(D11,D9) -> 3749349000
P13: LOI Details | U13: Due Diligence & Closing Timeline | AE13: Inspections | AR13: Deposits
C14: Property Name | D14: City | E14: State | F14: Stage | G14: Purchase Price | H14: IRR | I14: Property Type | J14: Total Slips/Racks | K14: Est Occ% | L14: Source | M14: Ownership | N14: SM Prospect? | O14: Acres | P14: Year | Q14: Submitted | R14: Signed | S14: Notes | AD14: Time in Deal | AE14: Third-Party Company | AQ14: Lender | AR14: Deposit #1 | AU14: Deposit #2 | AX14: Total Deposit
C15: Under Contract | U15: DD List Sent | V15: PSA Draftee | W15: PSA Signed | X15: DD Start Date | Y15: DD Period (Days) | Z15: DD Extension (Days) | AA15: DD Expiration | AB15: # of Days to Close | AC15: Closing Date | AD15: Days | AE15: PCA | AF15: Status | AG15: On-Site Date | AH15: ESA | AI15: Status | AJ15: On-Site Date | AK15: Survey | AL15: Status | AM15: On-Site Date | AN15: Title | AO15: Status | AP15: Date Commitments Rec'd | AQ15: Lender | AR15: # of Days after PSA | AS15: Date | AT15: Amount | AU15: # of Days after DD | AV15: Date | AW15: Amount | AX15: Amount
A16: 2025 | B16: Yes | C16: Dewey Beach Portfolio | D16: Dewey Beach | E16: DE | F16: Under Contract | G16: 18600000 | H16: 0.256 | I16: Marina | J16: =238+105 -> 343 | K16: 0.7 | L16: Off-Market | M16: Fee Simple; Leased | N16: =IF(L16="Broker","","Yes") -> Yes | O16: n/a | P16: 2025 | Q16: 45895 | R16: 45896 | S16: Attorney - Jessica Parker | U16: 45950 | V16: Buyer | W16: 45954 | X16: 45954 | Y16: 45 | Z16: 0 | AA16: 46037 | AB16: - | AC16: 46053 | AD16: =IF(R16="","",$A$1-R16) -> 222 | AE16: UES | AF16: Completed | AG16: 45986 | AH16: UES | AI16: Completed | AJ16: 45986 | AK16: Wilkins-Noble | AL16: Completed | AN16: First American | AO16: Completed | AQ16: Wells Fargo | AR16: 3 | AS16: =IF(W16="","TBD",W16+AR16) -> 45957 | AT16: 250000 | AU16: 3 | AV16: =IF(AA16="","TBD",AA16+AU16) -> 46040 | AW16: 350000 | AX16: =SUM(AW16,AT16) -> 600000
A17: 2025 | B17: Yes | C17: F3 Marina Fort Lauderdale | D17: Fort Lauderdale | E17: FL | F17: Under Contract | G17: 94000000 | H17: 0.228 | I17: Marina | J17: 254 | K17: 0.7 | L17: Broker | M17: Fee Simple | N17: =IF(L17="Broker","","Yes") | O17: 1.36 | P17: 2026 | Q17: 46043 | R17: 46059 | S17: Attorney - Jessica Parker; First LOI submitted 6/9/25, signed 6/19/25 | U17: 45828 | V17: Seller | W17: 45898 | X17: 46063 | Y17: =AA17-X17 -> 27 | Z17: 0 | AA17: 46090 | AB17: =AC17-AA17 -> 4 | AC17: 46094 | AD17: =IF(R17="","",$A$1-R17) -> 59 | AE17: UES | AF17: Completed | AG17: 45931 | AH17: UES | AI17: Completed | AJ17: 45931 | AK17: Avirom | AL17: Completed | AM17: 45925 | AN17: First American | AO17: Completed | AP17: 45840 | AQ17: Synovus | AR17: 3 | AS17: 45904 | AT17: 500000 | AU17: 3 | AV17: =IF(AA17="","TBD",AA17+AU17) -> 46093 | AW17: 3500000 | AX17: =SUM(AW17,AT17) -> 4000000
A18: 2025 | B18: Yes | C18: St. Thomas Portfolio (2-Prop) | D18: St. Thomas | E18: USVI | F18: Under Contract | G18: 36000000 | H18: 0.266 | I18: Marina | J18: =314+120 -> 434 | K18: 0.95 | L18: Broker | M18: Fee Simple; SLL | N18: Yes | O18: 7.05 | P18: 2025 | Q18: 45890 | R18: 45898 | S18: Attorneys - Jessica; Dudley (Dudley Newman Feuerzeig); Two submerged land leases that auto-renew; located in hurricane hole; catamarans; storage-centric; exclusivity until 10/13/25 | U18: 45902 | V18: Buyer | W18: 46107 | X18: =W18 -> 46107 | Y18: 75 | Z18: 0 | AA18: =X18+Y18 -> 46182 | AB18: 30 | AC18: =AA18+AB18 -> 46212 | AD18: =IF(R18="","",$A$1-R18) -> 220 | AE18: PR&A | AH18: PR&A | AK18: BM&A | AN18: First American | AQ18: Wells Fargo | AR18: 3 | AS18: =IF(W18="","TBD",W18+AR18) -> 46110 | AT18: 500000 | AU18: 3 | AV18: =IF(AA18="","TBD",AA18+AU18) -> 46185 | AW18: 500000 | AX18: =SUM(AW18,AT18) -> 1000000
AA19: =IF(X19="","",IF(Z19=OR(0,""),Y19+X19,X19+Y19+Z19)) | AC19: =IF(AA19="","",AB19+AA19) | AD19: =IF(R19="","",$A$1-R19)
C20: Under Contract Subtotal | D20: =COUNTA(C16:C19) -> 3 | G20: =SUM(G16:G19) -> 148600000 | J20: =SUM(J16:J19) -> 1031 | L20: =COUNTIF(L16:L19,"Off-Market") -> 1 | O20: =SUM(O16:O19) -> 8.41 | AT20: =SUM(AT16:AT19) -> 1250000 | AW20: =SUM(AW16:AW19) -> 4350000 | AX20: =SUM(AX19:AX19) -> 0
A21: =COUNTIF(B16:B19,"<>") -> 3 | B21: = # with Financials Received | L21: # Off-Market
A22: =COUNTIF(A16:A19,"2023") -> 0 | B22: = 2023 Deals
A23: =COUNTIF(A16:A19,"2024") -> 0 | B23: = 2024 Deals
A24: =COUNTIF(A16:A19,"2025") -> 3 | B24: = 2025 Deals
A25: =COUNTIF(A16:A19,"2026") -> 0 | B25: = 2026 Deals
C27: Under LOI | U27: DD List Sent | V27: PSA Draftee | W27: PSA Signed | X27: DD Start Date | Y27: DD Period (Days) | Z27: DD Extension (Days) | AA27: DD Expiration | AB27: # of Days to Close | AC27: Closing Date | AD27: Days | AQ27: Lender | AR27: # of Days after PSA | AS27: Date | AT27: Amount | AU27: # of Days after DD | AV27: Date | AW27: Amount | AX27: Amount
A28: 2025 | B28: Yes | C28: Surfside 3 Marina | D28: Lindenhurst | E28: NY | F28: Moving to Contract | G28: 19400000 | H28: 0.245 | I28: Marina | J28: =287 -> 287 | K28: 0.95 | L28: Off-Market | M28: Fee Simple | N28: =IF(L28="Broker","","Yes") -> Yes | O28: 13.387 | P28: 2025 | Q28: 45889 | R28: 45951 | S28: Finalizing underwriting | U28: 45951 | V28: Buyer | Y28: 60 | Z28: 0 | AA28: =IF(X28="","",IF(Z28=OR(0,""),Y28+X28,X28+Y28+Z28)) | AB28: 30 | AC28: =IF(AA28="","",AB28+AA28) | AD28: =IF(R28="","",$A$1-R28) -> 167 | AQ28: Bank | AR28: TBD | AS28: =IF(W28="","TBD",W28+AR28) -> TBD | AT28: 300000 | AU28: TBD | AV28: =IF(AA28="","TBD",AA28+AU28) -> TBD | AW28: 300000 | AX28: =SUM(AW28,AT28) -> 600000
A29: 2026 | B29: Yes | C29: Hurricane Hole Superyacht Marina | D29: Paradise Island | E29: Bahamas | F29: Under LOI | G29: 110000000 | H29: 0.194 | I29: Marina | J29: 90 | K29: TBD | L29: Broker | M29: Fee Simple; SLL | N29: =IF(L29="Broker","","Yes") | O29: =IFERROR(IF(AND(AND(M29<>"Market",M29<>"TBD"),N29<>"TBD"),N29/M29,""),"") | P29: 2026 | Q29: 46108 | R29: 46109 | S29: Open to varioius structures, including JV for just a portion of the deal - now with CBRE off-market | U29: 46111 | V29: Seller | X29: =R29+10 -> 46119 | Y29: 30 | Z29: 0 | AA29: =X29+Y29 -> 46149 | AB29: 30 | AC29: =AA29+AB29 -> 46179 | AD29: =IF(R29="","",$A$1-R29) -> 9 | AQ29: Wells Fargo | AR29: 3 | AS29: =IF(W29="","TBD",W29+AR29) -> TBD | AT29: 2000000 | AU29: 3 | AV29: =IF(AA29="","TBD",AA29+AU29) -> 46152 | AW29: 2000000 | AX29: =SUM(AW29,AT29) -> 4000000
AA30: =IF(X30="","",IF(Z30=OR(0,""),Y30+X30,X30+Y30+Z30)) | AC30: =IF(AA30="","",AB30+AA30) | AD30: =IF(R30="","",$A$1-R30)
C31: Under LOI Subtotal | D31: =COUNTA(C28:C30) -> 2 | G31: =SUM(G28:G30) -> 129400000 | J31: =SUM(J28:J30) -> 377 | L31: =COUNTIF(L18:L30,"Off-Market") -> 1 | O31: =SUM(O28:O30) -> 13.387 | AT31: =SUM(AT18:AT30) -> 4050000 | AW31: =SUM(AW18:AW30) -> 7150000 | AX31: =SUM(AX18:AX30) -> 5600000
A32: =COUNTIF(B18:B30,"<>") -> 8 | B32: = # with Financials Received | L32: # Off-Market
A33: =COUNTIF(A18:A30,"2023") -> 0 | B33: = 2023 Deals
A34: =COUNTIF(A18:A30,"2024") -> 0 | B34: = 2024 Deals
A35: =COUNTIF(A18:A30,"2025") -> 2 | B35: = 2025 Deals
A36: =COUNTIF(A18:A30,"2026") -> 1 | B36: = 2026 Deals
C38: Submitted Offers/To Be Submitted | AD38: Days
A39: 2025 | B39: Yes | C39: Port Tarpon Marina | D39: Tarpon Springs | E39: FL | F39: Ready to Re-Submit | G39: 13000000 | H39: TBD | I39: Marina; Development | J39: 460 | K39: 0.6 | L39: Off-Market | M39: Fee Simple; SLL | N39: Yes | P39: 2026 | Q39: 46037
A40: 2025 | B40: Yes | C40: Anclote Harbors Marina | D40: Tarpon Springs | E40: FL | F40: Ready to Re-Submit | G40: 19000000 | H40: 0.224 | I40: Marina | J40: 404 | K40: 0.65 | L40: Off-Market | M40: Fee Simple; SLL | N40: Yes | P40: 2026 | Q40: 46036
A41: 2026 | B41: Yes | C41: Legacy Harbour Marina | D41: Fort Myers | E41: FL | F41: Submitted | G41: 19500000 | H41: 0.228 | I41: Marina; Expansion | J41: 131 | K41: 0 | L41: Broker | M41: Fee Simple; SLL | O41: =3.16+8 -> 11.16 | P41: 2026 | Q41: 46045 | S41: In a $13M contract with Bellingham to redevelop; uplands can be sold separately; Phase II will allow for 37 more slips;
A42: 2026 | B42: Yes | C42: Keystone Point Marina | D42: Miami | E42: FL | F42: Submitted | G42: 47000000 | H42: 0.201 | I42: Marina | J42: =282+31 -> 313 | K42: 0.83 | L42: Off-Market | M42: Fee Simple | N42: Yes | O42: 4.77 | P42: 2026
A43: 2026 | B43: Yes | C43: Sunset Harbor Village | D43: Fort Myers | E43: FL | F43: Submitted | G43: 18250000 | H43: 0.261 | I43: Marina | J43: 125 | K43: 0.95 | L43: Broker | M43: Fee Simple | P43: 2026
...

Sheet PSA Critical Dates
B3: Property Name | C3: F3 Marina | D3: Sundance Marina | E3: Surfside 3 Marina | F3: Castaways Yacht Club | G3: Hingham Shipyard Marina
B4: PSA Signed | C4: =INDEX('M&A Deal Sheet'!$C$15:$AX$275,MATCH($B4,'M&A Deal Sheet'!$B$15:$B$275,0),MATCH(C$3,'M&A Deal Sheet'!$C$14:$AX$14,0)) -> #N/A | D4: =INDEX('M&A Deal Sheet'!$C$15:$AX$275,MATCH($B4,'M&A Deal Sheet'!$B$15:$B$275,0),MATCH(D$3,'M&A Deal Sheet'!$C$14:$AX$14,0)) -> #N/A | E4: =INDEX('M&A Deal Sheet'!$C$15:$AX$275,MATCH($B4,'M&A Deal Sheet'!$B$15:$B$275,0),MATCH(E$3,'M&A Deal Sheet'!$C$14:$AX$14,0)) -> #N/A | F4: =INDEX('M&A Deal Sheet'!$C$15:$AX$275,MATCH($B4,'M&A Deal Sheet'!$B$15:$B$275,0),MATCH(F$3,'M&A Deal Sheet'!$C$14:$AX$14,0)) -> #N/A | G4: =INDEX('M&A Deal Sheet'!$C$15:$AX$275,MATCH($B4,'M&A Deal Sheet'!$B$15:$B$275,0),MATCH(G$3,'M&A Deal Sheet'!$C$14:$AX$14,0)) -> #N/A
B5: DD List Due to Seller | C5: =INDEX('M&A Deal Sheet'!$C$15:$AX$275,MATCH($B5,'M&A Deal Sheet'!$B$15:$B$275,0),MATCH(C$3,'M&A Deal Sheet'!$C$14:$AX$14,0)) -> #N/A | D5: =INDEX('M&A Deal Sheet'!$C$15:$AX$275,MATCH($B5,'M&A Deal Sheet'!$B$15:$B$275,0),MATCH(D$3,'M&A Deal Sheet'!$C$14:$AX$14,0)) -> #N/A | E5: =INDEX('M&A Deal Sheet'!$C$15:$AX$275,MATCH($B5,'M&A Deal Sheet'!$B$15:$B$275,0),MATCH(E$3,'M&A Deal Sheet'!$C$14:$AX$14,0)) -> #N/A | F5: =INDEX('M&A Deal Sheet'!$C$15:$AX$275,MATCH($B5,'M&A Deal Sheet'!$B$15:$B$275,0),MATCH(F$3,'M&A Deal Sheet'!$C$14:$AX$14,0)) -> #N/A | G5: =INDEX('M&A Deal Sheet'!$C$15:$AX$275,MATCH($B5,'M&A Deal Sheet'!$B$15:$B$275,0),MATCH(G$3,'M&A Deal Sheet'!$C$14:$AX$14,0)) -> #N/A
B6: 1st Deposit Due | C6: =INDEX('M&A Deal Sheet'!$C$15:$AX$275,MATCH($B6,'M&A Deal Sheet'!$B$15:$B$275,0),MATCH(C$3,'M&A Deal Sheet'!$C$14:$AX$14,0)) -> #N/A | D6: =INDEX('M&A Deal Sheet'!$C$15:$AX$275,MATCH($B6,'M&A Deal Sheet'!$B$15:$B$275,0),MATCH(D$3,'M&A Deal Sheet'!$C$14:$AX$14,0)) -> #N/A | E6: =INDEX('M&A Deal Sheet'!$C$15:$AX$275,MATCH($B6,'M&A Deal Sheet'!$B$15:$B$275,0),MATCH(E$3,'M&A Deal Sheet'!$C$14:$AX$14,0)) -> #N/A | F6: =INDEX('M&A Deal Sheet'!$C$15:$AX$275,MATCH($B6,'M&A Deal Sheet'!$B$15:$B$275,0),MATCH(F$3,'M&A Deal Sheet'!$C$14:$AX$14,0)) -> #N/A | G6: =INDEX('M&A Deal Sheet'!$C$15:$AX$275,MATCH($B6,'M&A Deal Sheet'!$B$15:$B$275,0),MATCH(G$3,'M&A Deal Sheet'!$C$14:$AX$14,0)) -> #N/A
B7: 1st Deposit ($) | C7: =INDEX('M&A Deal Sheet'!$C$15:$AX$275,MATCH($B7,'M&A Deal Sheet'!$B$15:$B$275,0),MATCH(C$3,'M&A Deal Sheet'!$C$14:$AX$14,0)) -> #N/A | D7: =INDEX('M&A Deal Sheet'!$C$15:$AX$275,MATCH($B7,'M&A Deal Sheet'!$B$15:$B$275,0),MATCH(D$3,'M&A Deal Sheet'!$C$14:$AX$14,0)) -> #N/A | E7: =INDEX('M&A Deal Sheet'!$C$15:$AX$275,MATCH($B7,'M&A Deal Sheet'!$B$15:$B$275,0),MATCH(E$3,'M&A Deal Sheet'!$C$14:$AX$14,0)) -> #N/A | F7: =INDEX('M&A Deal Sheet'!$C$15:$AX$275,MATCH($B7,'M&A Deal Sheet'!$B$15:$B$275,0),MATCH(F$3,'M&A Deal Sheet'!$C$14:$AX$14,0)) -> #N/A | G7: =INDEX('M&A Deal Sheet'!$C$15:$AX$275,MATCH($B7,'M&A Deal Sheet'!$B$15:$B$275,0),MATCH(G$3,'M&A Deal Sheet'!$C$14:$AX$14,0)) -> #N/A
B8: Title | C8: =INDEX('M&A Deal Sheet'!$C$15:$AX$275,MATCH($B8,'M&A Deal Sheet'!$B$15:$B$275,0),MATCH(C$3,'M&A Deal Sheet'!$C$14:$AX$14,0)) -> #N/A | D8: =INDEX('M&A Deal Sheet'!$C$15:$AX$275,MATCH($B8,'M&A Deal Sheet'!$B$15:$B$275,0),MATCH(D$3,'M&A Deal Sheet'!$C$14:$AX$14,0)) -> #N/A | E8: =INDEX('M&A Deal Sheet'!$C$15:$AX$275,MATCH($B8,'M&A Deal Sheet'!$B$15:$B$275,0),MATCH(E$3,'M&A Deal Sheet'!$C$14:$AX$14,0)) -> #N/A | F8: =INDEX('M&A Deal Sheet'!$C$15:$AX$275,MATCH($B8,'M&A Deal Sheet'!$B$15:$B$275,0),MATCH(F$3,'M&A Deal Sheet'!$C$14:$AX$14,0)) -> #N/A | G8: =INDEX('M&A Deal Sheet'!$C$15:$AX$275,MATCH($B8,'M&A Deal Sheet'!$B$15:$B$275,0),MATCH(G$3,'M&A Deal Sheet'!$C$14:$AX$14,0)) -> #N/A
B9: Survey | C9: =INDEX('M&A Deal Sheet'!$C$15:$AX$275,MATCH($B9,'M&A Deal Sheet'!$B$15:$B$275,0),MATCH(C$3,'M&A Deal Sheet'!$C$14:$AX$14,0)) -> #N/A | D9: =INDEX('M&A Deal Sheet'!$C$15:$AX$275,MATCH($B9,'M&A Deal Sheet'!$B$15:$B$275,0),MATCH(D$3,'M&A Deal Sheet'!$C$14:$AX$14,0)) -> #N/A | E9: =INDEX('M&A Deal Sheet'!$C$15:$AX$275,MATCH($B9,'M&A Deal Sheet'!$B$15:$B$275,0),MATCH(E$3,'M&A Deal Sheet'!$C$14:$AX$14,0)) -> #N/A | F9: =INDEX('M&A Deal Sheet'!$C$15:$AX$275,MATCH($B9,'M&A Deal Sheet'!$B$15:$B$275,0),MATCH(F$3,'M&A Deal Sheet'!$C$14:$AX$14,0)) -> #N/A | G9: =INDEX('M&A Deal Sheet'!$C$15:$AX$275,MATCH($B9,'M&A Deal Sheet'!$B$15:$B$275,0),MATCH(G$3,'M&A Deal Sheet'!$C$14:$AX$14,0)) -> #N/A
B10: ESA | C10: =INDEX('M&A Deal Sheet'!$C$15:$AX$275,MATCH($B10,'M&A Deal Sheet'!$B$15:$B$275,0),MATCH(C$3,'M&A Deal Sheet'!$C$14:$AX$14,0)) -> #N/A | D10: =INDEX('M&A Deal Sheet'!$C$15:$AX$275,MATCH($B10,'M&A Deal Sheet'!$B$15:$B$275,0),MATCH(D$3,'M&A Deal Sheet'!$C$14:$AX$14,0)) -> #N/A | E10: =INDEX('M&A Deal Sheet'!$C$15:$AX$275,MATCH($B10,'M&A Deal Sheet'!$B$15:$B$275,0),MATCH(E$3,'M&A Deal Sheet'!$C$14:$AX$14,0)) -> #N/A | F10: =INDEX('M&A Deal Sheet'!$C$15:$AX$275,MATCH($B10,'M&A Deal Sheet'!$B$15:$B$275,0),MATCH(F$3,'M&A Deal Sheet'!$C$14:$AX$14,0)) -> #N/A | G10: =INDEX('M&A Deal Sheet'!$C$15:$AX$275,MATCH($B10,'M&A Deal Sheet'!$B$15:$B$275,0),MATCH(G$3,'M&A Deal Sheet'!$C$14:$AX$14,0)) -> #N/A
B11: PCR | C11: =INDEX('M&A Deal Sheet'!$C$15:$AX$275,MATCH($B11,'M&A Deal Sheet'!$B$15:$B$275,0),MATCH(C$3,'M&A Deal Sheet'!$C$14:$AX$14,0)) -> #N/A | D11: =INDEX('M&A Deal Sheet'!$C$15:$AX$275,MATCH($B11,'M&A Deal Sheet'!$B$15:$B$275,0),MATCH(D$3,'M&A Deal Sheet'!$C$14:$AX$14,0)) -> #N/A | E11: =INDEX('M&A Deal Sheet'!$C$15:$AX$275,MATCH($B11,'M&A Deal Sheet'!$B$15:$B$275,0),MATCH(E$3,'M&A Deal Sheet'!$C$14:$AX$14,0)) -> #N/A | F11: =INDEX('M&A Deal Sheet'!$C$15:$AX$275,MATCH($B11,'M&A Deal Sheet'!$B$15:$B$275,0),MATCH(F$3,'M&A Deal Sheet'!$C$14:$AX$14,0)) -> #N/A | G11: =INDEX('M&A Deal Sheet'!$C$15:$AX$275,MATCH($B11,'M&A Deal Sheet'!$B$15:$B$275,0),MATCH(G$3,'M&A Deal Sheet'!$C$14:$AX$14,0)) -> #N/A
B12: DD Expiration | C12: =INDEX('M&A Deal Sheet'!$C$15:$AX$275,MATCH($B12,'M&A Deal Sheet'!$B$15:$B$275,0),MATCH(C$3,'M&A Deal Sheet'!$C$14:$AX$14,0)) -> #N/A | D12: =INDEX('M&A Deal Sheet'!$C$15:$AX$275,MATCH($B12,'M&A Deal Sheet'!$B$15:$B$275,0),MATCH(D$3,'M&A Deal Sheet'!$C$14:$AX$14,0)) -> #N/A | E12: =INDEX('M&A Deal Sheet'!$C$15:$AX$275,MATCH($B12,'M&A Deal Sheet'!$B$15:$B$275,0),MATCH(E$3,'M&A Deal Sheet'!$C$14:$AX$14,0)) -> #N/A | F12: =INDEX('M&A Deal Sheet'!$C$15:$AX$275,MATCH($B12,'M&A Deal Sheet'!$B$15:$B$275,0),MATCH(F$3,'M&A Deal Sheet'!$C$14:$AX$14,0)) -> #N/A | G12: =INDEX('M&A Deal Sheet'!$C$15:$AX$275,MATCH($B12,'M&A Deal Sheet'!$B$15:$B$275,0),MATCH(G$3,'M&A Deal Sheet'!$C$14:$AX$14,0)) -> #N/A
B13: 2nd Deposit Due | C13: =INDEX('M&A Deal Sheet'!$C$15:$AX$275,MATCH($B13,'M&A Deal Sheet'!$B$15:$B$275,0),MATCH(C$3,'M&A Deal Sheet'!$C$14:$AX$14,0)) -> #N/A | D13: =INDEX('M&A Deal Sheet'!$C$15:$AX$275,MATCH($B13,'M&A Deal Sheet'!$B$15:$B$275,0),MATCH(D$3,'M&A Deal Sheet'!$C$14:$AX$14,0)) -> #N/A | E13: =INDEX('M&A Deal Sheet'!$C$15:$AX$275,MATCH($B13,'M&A Deal Sheet'!$B$15:$B$275,0),MATCH(E$3,'M&A Deal Sheet'!$C$14:$AX$14,0)) -> #N/A | F13: =INDEX('M&A Deal Sheet'!$C$15:$AX$275,MATCH($B13,'M&A Deal Sheet'!$B$15:$B$275,0),MATCH(F$3,'M&A Deal Sheet'!$C$14:$AX$14,0)) -> #N/A | G13: =INDEX('M&A Deal Sheet'!$C$15:$AX$275,MATCH($B13,'M&A Deal Sheet'!$B$15:$B$275,0),MATCH(G$3,'M&A Deal Sheet'!$C$14:$AX$14,0)) -> #N/A
B14: 2nd Deposit ($) | C14: =INDEX('M&A Deal Sheet'!$C$15:$AX$275,MATCH($B14,'M&A Deal Sheet'!$B$15:$B$275,0),MATCH(C$3,'M&A Deal Sheet'!$C$14:$AX$14,0)) -> #N/A | D14: =INDEX('M&A Deal Sheet'!$C$15:$AX$275,MATCH($B14,'M&A Deal Sheet'!$B$15:$B$275,0),MATCH(D$3,'M&A Deal Sheet'!$C$14:$AX$14,0)) -> #N/A | E14: =INDEX('M&A Deal Sheet'!$C$15:$AX$275,MATCH($B14,'M&A Deal Sheet'!$B$15:$B$275,0),MATCH(E$3,'M&A Deal Sheet'!$C$14:$AX$14,0)) -> #N/A | F14: =INDEX('M&A Deal Sheet'!$C$15:$AX$275,MATCH($B14,'M&A Deal Sheet'!$B$15:$B$275,0),MATCH(F$3,'M&A Deal Sheet'!$C$14:$AX$14,0)) -> #N/A | G14: =INDEX('M&A Deal Sheet'!$C$15:$AX$275,MATCH($B14,'M&A Deal Sheet'!$B$15:$B$275,0),MATCH(G$3,'M&A Deal Sheet'!$C$14:$AX$14,0)) -> #N/A
B15: Closing Date | C15: =INDEX('M&A Deal Sheet'!$C$15:$AX$275,MATCH($B15,'M&A Deal Sheet'!$B$15:$B$275,0),MATCH(C$3,'M&A Deal Sheet'!$C$14:$AX$14,0)) -> #N/A | D15: =INDEX('M&A Deal Sheet'!$C$15:$AX$275,MATCH($B15,'M&A Deal Sheet'!$B$15:$B$275,0),MATCH(D$3,'M&A Deal Sheet'!$C$14:$AX$14,0)) -> #N/A | E15: =INDEX('M&A Deal Sheet'!$C$15:$AX$275,MATCH($B15,'M&A Deal Sheet'!$B$15:$B$275,0),MATCH(E$3,'M&A Deal Sheet'!$C$14:$AX$14,0)) -> #N/A | F15: =INDEX('M&A Deal Sheet'!$C$15:$AX$275,MATCH($B15,'M&A Deal Sheet'!$B$15:$B$275,0),MATCH(F$3,'M&A Deal Sheet'!$C$14:$AX$14,0)) -> #N/A | G15: =INDEX('M&A Deal Sheet'!$C$15:$AX$275,MATCH($B15,'M&A Deal Sheet'!$B$15:$B$275,0),MATCH(G$3,'M&A Deal Sheet'!$C$14:$AX$14,0)) -> #N/A

Sheet Regions
A1: CT | B1: =COUNTIF('M&A Deal Sheet'!$E:$E,A1) -> 2 | C1: Northeast | I1: Alabama | J1: AL | L1: Alabama | M1: =VLOOKUP(L1, $I$1:$J$50, 2, FALSE) -> AL | N1: CT | O1: =COUNTIF(M:M,N1) -> 17
A2: ME | B2: =COUNTIF('M&A Deal Sheet'!$E:$E,A2) -> 2 | C2: Northeast | E2: Northeast | F2: =SUMIFS($B:$B,$C:$C,E2) -> 8 | G2: =F2/$F$7 -> 0.04 | I2: Alaska | J2: AK | L2: Alabama | M2: =VLOOKUP(L2, $I$1:$J$50, 2, FALSE) -> AL | N2: ME | O2: =COUNTIF(M:M,N2) -> 3 | R2: Northeast | S2: =SUMIFS($O:$O,$C:$C,R2) -> 42 | T2: =S2/$S$7 -> 0.10659898
A3: MA | B3: =COUNTIF('M&A Deal Sheet'!$E:$E,A3) -> 3 | C3: Northeast | E3: Midwest | F3: =SUMIFS($B:$B,$C:$C,E3) -> 16 | G3: =F3/$F$7 -> 0.08 | I3: Arizona | J3: AZ | L3: Alabama | M3: =VLOOKUP(L3, $I$1:$J$50, 2, FALSE) -> AL | N3: MA | O3: =COUNTIF(M:M,N3) -> 15 | R3: Midwest | S3: =SUMIFS($O:$O,$C:$C,R3) -> 12 | T3: =S3/$S$7 -> 0.030456853
A4: NH | B4: =COUNTIF('M&A Deal Sheet'!$E:$E,A4) -> 1 | C4: Northeast | E4: South | F4: =SUMIFS($B:$B,$C:$C,E4) -> 99 | G4: =F4/$F$7 -> 0.495 | I4: Arkansas | J4: AR | L4: Alabama | M4: =VLOOKUP(L4, $I$1:$J$50, 2, FALSE) -> AL | N4: NH | O4: =COUNTIF(M:M,N4) -> 2 | R4: South | S4: =SUMIFS($O:$O,$C:$C,R4) -> 207 | T4: =S4/$S$7 -> 0.52538071
A5: RI | B5: =COUNTIF('M&A Deal Sheet'!$E:$E,A5) -> 0 | C5: Northeast | E5: Mid-Atlantic | F5: =SUMIFS($B:$B,$C:$C,E5) -> 48 | G5: =F5/$F$7 -> 0.24 | I5: California | J5: CA | L5: Alabama | M5: =VLOOKUP(L5, $I$1:$J$50, 2, FALSE) -> AL | N5: RI | O5: =COUNTIF(M:M,N5) -> 5 | R5: Mid-Atlantic | S5: =SUMIFS($O:$O,$C:$C,R5) -> 96 | T5: =S5/$S$7 -> 0.24365482
A6: VT | B6: =COUNTIF('M&A Deal Sheet'!$E:$E,A6) -> 0 | C6: Northeast | E6: West | F6: =SUMIFS($B:$B,$C:$C,E6) -> 29 | G6: =F6/$F$7 -> 0.145 | I6: Colorado | J6: CO | L6: Alabama | M6: =VLOOKUP(L6, $I$1:$J$50, 2, FALSE) -> AL | N6: VT | O6: =COUNTIF(M:M,N6) -> 0 | R6: West | S6: =SUMIFS($O:$O,$C:$C,R6) -> 37 | T6: =S6/$S$7 -> 0.093908629
A7: NJ | B7: =COUNTIF('M&A Deal Sheet'!$E:$E,A7) -> 10 | C7: Mid-Atlantic | F7: =SUM(F2:F6) -> 200 | I7: Connecticut | J7: CT | L7: Alabama | M7: =VLOOKUP(L7, $I$1:$J$50, 2, FALSE) -> AL | N7: NJ | O7: =COUNTIF(M:M,N7) -> 25 | S7: =SUM(S2:S6) -> 394
A8: NY | B8: =COUNTIF('M&A Deal Sheet'!$E:$E,A8) -> 17 | C8: Mid-Atlantic | I8: Delaware | J8: DE | L8: Alabama | M8: =VLOOKUP(L8, $I$1:$J$50, 2, FALSE) -> AL | N8: NY | O8: =COUNTIF(M:M,N8) -> 26
A9: PA | B9: =COUNTIF('M&A Deal Sheet'!$E:$E,A9) -> 1 | C9: Mid-Atlantic | I9: Florida | J9: FL | L9: Alabama | M9: =VLOOKUP(L9, $I$1:$J$50, 2, FALSE) -> AL | N9: PA | O9: =COUNTIF(M:M,N9) -> 2
A10: IL | B10: =COUNTIF('M&A Deal Sheet'!$E:$E,A10) -> 1 | C10: Midwest | I10: Georgia | J10: GA | L10: Alabama | M10: =VLOOKUP(L10, $I$1:$J$50, 2, FALSE) -> AL | N10: IL | O10: =COUNTIF(M:M,N10) -> 3
A11: IN | B11: =COUNTIF('M&A Deal Sheet'!$E:$E,A11) -> 2 | C11: Midwest | I11: Hawaii | J11: HI | L11: Arizona | M11: =VLOOKUP(L11, $I$1:$J$50, 2, FALSE) -> AZ | N11: IN | O11: =COUNTIF(M:M,N11) -> 0
A12: MI | B12: =COUNTIF('M&A Deal Sheet'!$E:$E,A12) -> 6 | C12: Midwest | I12: Idaho | J12: ID | L12: Arizona | M12: =VLOOKUP(L12, $I$1:$J$50, 2, FALSE) -> AZ | N12: MI | O12: =COUNTIF(M:M,N12) -> 4
A13: OH | B13: =COUNTIF('M&A Deal Sheet'!$E:$E,A13) -> 2 | C13: Midwest | I13: Illinois | J13: IL | L13: Arkansas | M13: =VLOOKUP(L13, $I$1:$J$50, 2, FALSE) -> AR | N13: OH | O13: =COUNTIF(M:M,N13) -> 3
A14: WI | B14: =COUNTIF('M&A Deal Sheet'!$E:$E,A14) -> 0 | C14: Midwest | I14: Indiana | J14: IN | L14: Arkansas | M14: =VLOOKUP(L14, $I$1:$J$50, 2, FALSE) -> AR | N14: WI | O14: =COUNTIF(M:M,N14) -> 0
A15: IA | B15: =COUNTIF('M&A Deal Sheet'!$E:$E,A15) -> 0 | C15: Midwest | I15: Iowa | J15: IA | L15: Arkansas | M15: =VLOOKUP(L15, $I$1:$J$50, 2, FALSE) -> AR | N15: IA | O15: =COUNTIF(M:M,N15) -> 0
A16: KS | B16: =COUNTIF('M&A Deal Sheet'!$E:$E,A16) -> 0 | C16: Midwest | I16: Kansas | J16: KS | L16: Arkansas | M16: =VLOOKUP(L16, $I$1:$J$50, 2, FALSE) -> AR | N16: KS | O16: =COUNTIF(M:M,N16) -> 1
A17: MN | B17: =COUNTIF('M&A Deal Sheet'!$E:$E,A17) -> 0 | C17: Midwest | I17: Kentucky | J17: KY | L17: Arkansas | M17: =VLOOKUP(L17, $I$1:$J$50, 2, FALSE) -> AR | N17: MN | O17: =COUNTIF(M:M,N17) -> 0
A18: MO | B18: =COUNTIF('M&A Deal Sheet'!$E:$E,A18) -> 4 | C18: Midwest | I18: Louisiana | J18: LA | L18: Arkansas | M18: =VLOOKUP(L18, $I$1:$J$50, 2, FALSE) -> AR | N18: MO | O18: =COUNTIF(M:M,N18) -> 1
A19: NE | B19: =COUNTIF('M&A Deal Sheet'!$E:$E,A19) -> 1 | C19: Midwest | I19: Maine | J19: ME | L19: Arkansas | M19: =VLOOKUP(L19, $I$1:$J$50, 2, FALSE) -> AR | N19: NE | O19: =COUNTIF(M:M,N19) -> 0
... A50: OR | B50: =COUNTIF('M&A Deal Sheet'!$E:$E,A50) -> 2 | C50: West | I50: Wyoming | J50: WY | L50: Connecticut | M50: =VLOOKUP(L50, $I$1:$J$50, 2, FALSE) -> CT | N50: OR | O50: =COUNTIF(M:M,N50) -> 3
A51: WA | B51: =COUNTIF('M&A Deal Sheet'!$E:$E,A51) -> 8 | C51: West | L51: DC | M51: DC | N51: WA | O51: =COUNTIF(M:M,N51) -> 16
B52: =SUM(B1:B51) -> 200 | L52: Florida | M52: =VLOOKUP(L52, $I$1:$J$50, 2, FALSE) -> FL
L53: Florida | M53: =VLOOKUP(L53, $I$1:$J$50, 2, FALSE) -> FL
L54: Florida | M54: =VLOOKUP(L54, $I$1:$J$50, 2, FALSE) -> FL
L55: Florida | M55: =VLOOKUP(L55, $I$1:$J$50, 2, FALSE) -> FL
L56: Florida | M56: =VLOOKUP(L56, $I$1:$J$50, 2, FALSE) -> FL
L57: Florida | M57: =VLOOKUP(L57, $I$1:$J$50, 2, FALSE) -> FL
L58: Florida | M58: =VLOOKUP(L58, $I$1:$J$50, 2, FALSE) -> FL
L59: Florida | M59: =VLOOKUP(L59, $I$1:$J$50, 2, FALSE) -> FL
L60: Florida | M60: =VLOOKUP(L60, $I$1:$J$50, 2, FALSE) -> FL
L61: Florida | M61: =VLOOKUP(L61, $I$1:$J$50, 2, FALSE) -> FL
L62: Florida | M62: =VLOOKUP(L62, $I$1:$J$50, 2, FALSE) -> FL
L63: Florida | M63: =VLOOKUP(L63, $I$1:$J$50, 2, FALSE) -> FL
L64: Florida | M64: =VLOOKUP(L64, $I$1:$J$50, 2, FALSE) -> FL
... L394: Washington | M394: =VLOOKUP(L394, $I$1:$J$50, 2, FALSE) -> WA

Sheet M&A Deal Sheet - Q4 BD Slide
B1: M&A Deal Sheet
E2: 2025 YTD | H2: 2024 Total
B4: Under Contract | C4: =F15 -> 0 | E4: Deals Evaluated | F4: ='Deal Tracker'!C175 -> 15 | H4: Deals Evaluated | I4: ='Deal Tracker'!C174 -> 94
B5: Submitted Offers/To Be Submitted | C5: =F23 -> 125000000 | E5: Financials Received | F5: ='Deal Tracker'!B175 -> 12 | G5: =IFERROR(F5/$F$4,"n/a") -> 0.8 | H5: Financials Received | I5: ='Deal Tracker'!B174 -> 62 | J5: =I5/I4 -> 0.65957447
B6: Analyzing | C6: =F39 -> 244000000 | E6: LOIs Issued | F6: 3 | H6: LOIs Issued | I6: 1
B7: Long-Term | C7: ='Deal Tracker'!M68 -> 184000000 | E7: LOIs Signed | F7: =C15 -> 0 | H7: LOIs Signed | I7: =C15 -> 0
C8: =SUM(C4:C7) -> 553000000 | E8: Closed/Expected to Close | F8: 0 | H8: Closed/Expected to Close | I8: =C15 -> 0
E9: Off-Market | F9: ='Deal Tracker'!J175 -> 3 | G9: =IFERROR(F9/$F$4,"n/a") -> 0.2 | H9: Off-Market | I9: ='Deal Tracker'!J174 -> 50 | J9: =I9/I4 -> 0.53191489
B10: Passed On/Lost | C10: ='Deal Tracker'!M164 -> 751450000 | E10: SM Prospects | F10: ='Deal Tracker'!P175 -> 11 | G10: =IFERROR(F10/$F$4,"n/a") -> 0.73333333 | H10: SM Prospects | I10: ='Deal Tracker'!P174 -> 40 | J10: =I10/I4 -> 0.42553191
B12: Property Name | C12: City | D12: State | E12: Stage | F12: Purchase Price | G12: Property Type | H12: Total Slips/Racks | I12: Est Occ% | J12: Source | K12: Ownership | L12: Gross IRR | M12: Acres | N12: Notes | O12: Closing Status
B13: Under Contract | O13: Deposit Dates | P13: Closing Date | Q13: 3rd Party Reports | R13: Debt
B15: Under Contract Subtotal | C15: =COUNTA(B14:B14) -> 0 | F15: =SUM(F14:F14) -> 0 | H15: =SUM(H14:H14) -> 0 | M15: =SUM(M14:M14) -> 0
B17: Submitted Offers/To Be Submitted
B18: Hingham Shipyard Marinas | C18: Boston | D18: MA | E18: LOI Submitted | F18: 62000000 | G18: Marina | H18: =550+85 -> 635 | I18: 95-100% | J18: Off-Market | K18: Fee Simple | L18: 0.25 | M18: 55.16
B19: Castaways Yacht Club | C19: New Rochelle | D19: NY | E19: LOI Submitted | F19: 20000000 | G19: Marina | H19: =130+70 -> 200 | I19: 0.98 | J19: Broker | K19: Fee Simple | L19: 0.26
B20: Sundance Marine | C20: Jensen Beach | D20: FL | E20: LOI Submitted | F20: 17000000 | G20: Marina | H20: 270 | I20: 0.95 | J20: Broker | K20: Fee Simple | L20: 0.25
B21: Hidden Harbor Marina | C21: Sarasota | D21: FL | E21: LOI to be Submitted | F21: 26000000 | G21: Marina | H21: 325 | I21: 95-100% | J21: Off-Market | K21: Fee Simple | L21: 0.24 | M21: 2.71 | N21: Restaurant lease recently signed; potential disconnect on price if seller does not get real with boat rentals; Quality Boats is renewing their lease at a higher rate per seller.
B23: Submitted/To Be Submitted Subtotal | C23: =COUNTA(B18:B22) -> 4 | F23: =SUM(F18:F22) -> 125000000 | H23: =SUM(H18:H22) -> 1430 | M23: =SUM(M18:M22) -> 57.87
B25: Analyzing
B26: Eastport Yacht Center | C26: Eastport | D26: MD | E26: Updating | F26: 10500000 | G26: Marina | H26: 80 | I26: 0 | J26: Off-Market | K26: Fee Simple | L26: 0.29
B27: Surfside 3 Marina | C27: Lindenhurst | D27: NY | E27: Updating | F27: 16000000 | G27: Marina | H27: 550 | I27: 0.95 | J27: Off-Market | K27: Fee Simple | L27: 0.27
B28: Kirkland Homeport Marina | C28: Kirkland | D28: WA | E28: Analyzing | F28: 40000000 | G28: Marina | H28: 118 | I28: 1 | J28: Off-Market | K28: Fee Simple
B29: King Harbor Marina | C29: Redondo Beach | D29: CA | E29: Updating | F29: 90000000 | G29: Marina | H29: 800 | I29: 0.9 | J29: Broker | K29: Leased
B30: Madeira Beach - Development | C30: Madeira Beaach | D30: FL | E30: Analyzing | F30: TBD | G30: Marina | H30: 80 | I30: 0 | J30: Off-Market | K30: Fee Simple
B31: Sands Harbor Resort & Marina | C31: Pompano Beach | D31: FL | E31: Completed | F31: 20000000 | G31: Marina | H31: 50 | I31: 0.95 | J31: Off-Market | K31: Fee Simple | L31: 0.24
B32: Cat's Paw Marina | C32: St. Augustine | D32: FL | E32: Completed | F32: 15000000 | G32: Marina | H32: 700 | I32: 0.95 | J32: Broker | K32: Fee Simple | L32: 0.25
B33: Mangrove Marina | C33: Key Largo | D33: FL | E33: Analyzing | F33: 12500000 | G33: Marina | H33: 229 | I33: 0.95 | J33: Broker | K33: Fee Simple | M33: 21.35
B34: Port Dania - Development Opportunity | C34: Dania Beach | D34: FL | E34: Analyzing | F34: TBD | G34: Marina | H34: 240 | I34: 0 | J34: Broker | K34: Fee Simple
B35: Sundance Marinas Portfolio | C35: Portland | D35: OR | E35: Analyzing | F35: 40000000 | G35: Marina | H35: 650 | I35: TBD | J35: Broker | K35: Fee Simple/Leased
B36: Xtreme Cove Marina | C36: Eufaula | D36: OK | E36: Analyzing | F36: TBD | G36: Marina; RV | H36: 404 | I36: TBD | J36: Broker | K36: Leased
B37: JDF Marina | C37: Panama City Beach | D37: FL | E37: Analyzing | F37: TBD | G37: Marina | J37: Broker | K37: Fee Simple
B39: Analyzing Subtotal | C39: =COUNTA(C26:C38) -> 12 | F39: =SUM(F26:F38) -> 244000000 | H39: =SUM(H26:H38) -> 3901 | M39: =SUM(M26:M38) -> 21.35
B41: Long-Term
B42: Bay Bridge Marina | C42: Annapolis | D42: MD | E42: On Hold | F42: 19000000 | G42: Marina | H42: 380 | I42: 0.92 | J42: Off-Market | K42: Fee Simple | L42: Yes | M42: 25
B43: Prairie Creek Marina | C43: Rogers | D43: AR | E43: Lost | F43: 28000000 | G43: Marina | H43: =SUM(#REF!,#REF!,#REF!,#REF!) -> #REF! | I43: 1 | J43: Off-Market | K43: USACOE Lease | L43: Yes | M43: 28 | N43: Lost out; might be opportunity to revisit.
B44: Shiloh Marina | C44: Greers Ferry | D44: AR | E44: On Hold | F44: 16500000 | G44: Marina | H44: =SUM(#REF!,#REF!,#REF!,#REF!) -> #REF! | I44: 1 | J44: Off-Market | K44: USACOE Lease | L44: Yes
B45: Hoosier Hills Marina | C45: Celestine | D45: IN | E45: On Hold | F45: 11000000 | G45: Marina | H45: =SUM(#REF!,#REF!,#REF!,#REF!) -> #REF! | I45: 1 | J45: Off-Market | K45: USACOE Lease | L45: Yes | M45: 20
B46: Surfside 3 Marina | C46: Lindenhurst | D46: NY | E46: On Hold | F46: 25000000 | G46: Marina | H46: =SUM(#REF!,#REF!,#REF!,#REF!) -> #REF! | I46: 0.93 | J46: Off-Market | K46: Fee Simple; SLL | L46: Yes | M46: 13 | N46: Oakdale & GC are more attractive (capacity, layout of site, surrounding area).
B47: Twin Creeks Marina | C47: Winchester | D47: TN | E47: On Hold | F47: 27000000 | G47: Marina; RV | H47: =SUM(#REF!,#REF!,#REF!,#REF!) -> #REF! | I47: 0.95 | J47: Broker | K47: Leased | L47: Yes | M47: 80
B48: Marina Village Yacht Harbor | C48: Alameda | D48: CA | E48: On Hold | F48: 45000000 | G48: Marina | H48: =SUM(#REF!,#REF!,#REF!,#REF!) -> #REF! | I48: 0.93 | J48: Off-Market | K48: Fee Simple | L48: Yes | M48: 30
...
